DEBUG flower 2022-01-11 02:34:33,631 | connection.py:36 | ChannelConnectivity.IDLE
DEBUG flower 2022-01-11 02:34:33,632 | connection.py:36 | ChannelConnectivity.CONNECTING
DEBUG flower 2022-01-11 02:34:33,633 | connection.py:36 | ChannelConnectivity.READY
INFO flower 2022-01-11 02:34:33,675 | app.py:61 | Opened (insecure) gRPC connection
DEBUG flower 2022-01-11 02:34:33,836 | connection.py:68 | Insecure gRPC channel closed
Files already downloaded and verified
Files already downloaded and verified
Traceback (most recent call last):
  File "./client.py", line 126, in <module>
    main()
  File "./client.py", line 122, in main
    fl.client.start_numpy_client("[::]:8080", client=CifarClient())
  File "/home/azureuser/.local/lib/python3.8/site-packages/flwr/client/app.py", line 112, in start_numpy_client
    start_client(
  File "/home/azureuser/.local/lib/python3.8/site-packages/flwr/client/app.py", line 64, in start_client
    server_message = receive()
  File "/home/azureuser/.local/lib/python3.8/site-packages/flwr/client/grpc_client/connection.py", line 60, in <lambda>
    receive: Callable[[], ServerMessage] = lambda: next(server_message_iterator)
  File "/home/azureuser/.local/lib/python3.8/site-packages/grpc/_channel.py", line 426, in __next__
    return self._next()
  File "/home/azureuser/.local/lib/python3.8/site-packages/grpc/_channel.py", line 824, in _next
    raise StopIteration()
StopIteration
Error in sys.excepthook:
Traceback (most recent call last):
  File "/usr/lib/python3/dist-packages/apport_python_hook.py", line 72, in apport_excepthook
    from apport.fileutils import likely_packaged, get_recent_crashes
  File "/usr/lib/python3/dist-packages/apport/__init__.py", line 5, in <module>
    from apport.report import Report
  File "/usr/lib/python3/dist-packages/apport/report.py", line 32, in <module>
    import apport.fileutils
  File "/usr/lib/python3/dist-packages/apport/fileutils.py", line 27, in <module>
    from apport.packaging_impl import impl as packaging
  File "/usr/lib/python3/dist-packages/apport/packaging_impl.py", line 23, in <module>
    import apt
  File "/usr/lib/python3/dist-packages/apt/__init__.py", line 36, in <module>
    apt_pkg.init_system()
apt_pkg.Error: E:Error reading the CPU table

Original exception was:
Traceback (most recent call last):
  File "./client.py", line 126, in <module>
    main()
  File "./client.py", line 122, in main
    fl.client.start_numpy_client("[::]:8080", client=CifarClient())
  File "/home/azureuser/.local/lib/python3.8/site-packages/flwr/client/app.py", line 112, in start_numpy_client
    start_client(
  File "/home/azureuser/.local/lib/python3.8/site-packages/flwr/client/app.py", line 64, in start_client
    server_message = receive()
  File "/home/azureuser/.local/lib/python3.8/site-packages/flwr/client/grpc_client/connection.py", line 60, in <lambda>
    receive: Callable[[], ServerMessage] = lambda: next(server_message_iterator)
  File "/home/azureuser/.local/lib/python3.8/site-packages/grpc/_channel.py", line 426, in __next__
    return self._next()
  File "/home/azureuser/.local/lib/python3.8/site-packages/grpc/_channel.py", line 824, in _next
    raise StopIteration()
StopIteration
